<?xml version="1.0"?>
<robot name="Universal_Robots_UR3">
  <!-- Configuration of the part called 'Base 1'. -->
  <link name="base_link">
    <visual>
      <geometry>
        <mesh filename="/Mesh/Visual/Base.stl"/>
      </geometry>
      <material name="Custom_Color">
        <color rgba="0.90 0.90 0.90 1.0"/>
      </material>
    </visual>
    <collision>
      <geometry>
        <mesh filename="/Mesh/Collision/Base.stl"/>
      </geometry>
    </collision>
    <inertial>
      <mass value="2.0"/>
      <origin rpy="0.0 0.0 0.0" xyz="0.00000 -0.00001 0.04302"/>
      <inertia ixx="0.00396" ixy="0.0" ixz="0.0" iyy="0.00397" iyz="0.0" izz="0.00546"/>
    </inertial>
  </link>
  <!-- Configuration of the part called 'Joint 1'. -->
  <joint name="joint_1" type="revolute">
    <parent link="base_link"/>
    <child link="link_1"/>
    <origin rpy="0.0 0.0 0.0" xyz="0.0 0.0 0.15190"/>
    <axis xyz="0 0 1"/>
    <limit effort="28.0" lower="-3.14159" upper="3.14159" velocity="3.14"/>
  </joint>
  <link name="link_1">
    <visual>
      <geometry>
        <mesh filename="/Mesh/Visual/Joint_1.stl"/>
      </geometry>
      <material name="Custom_Color">
        <color rgba="0.90 0.90 0.90 1.0"/>
      </material>
    </visual>
    <collision>
      <geometry>
        <mesh filename="/Mesh/Collision/Joint_1.stl"/>
      </geometry>
    </collision>
    <inertial>
      <mass value="1.26"/>
      <origin rpy="0.0 0.0 0.0" xyz="-0.10402 -0.00001 0.02942"/>
      <inertia ixx="0.00304" ixy="0.0" ixz="0.0" iyy="0.00390" iyz="0.0" izz="0.00418"/>
    </inertial>
  </link>
  <!-- Configuration of the part called 'Joint 2'. -->
  <joint name="joint_2" type="revolute">
    <parent link="link_1"/>
    <child link="link_2"/>
    <origin rpy="1.57080 0.0 0.0" xyz="0.0 0.0 0.0"/>
    <axis xyz="0 0 1"/>
    <limit effort="28.0" lower="-3.14159" upper="3.14159" velocity="3.14"/>
  </joint>
  <link name="link_2">
    <visual>
      <geometry>
        <mesh filename="/Mesh/Visual/Joint_2.stl"/>
      </geometry>
      <material name="Custom_Color">
        <color rgba="0.90 0.90 0.90 1.0"/>
      </material>
    </visual>
    <collision>
      <geometry>
        <mesh filename="/Mesh/Collision/Joint_2.stl"/>
      </geometry>
    </collision>
    <inertial>
      <mass value="1.26"/>
      <origin rpy="0.0 0.0 0.0" xyz="-0.10402 -0.00001 0.02942"/>
      <inertia ixx="0.03306" ixy="0.0" ixz="0.0" iyy="0.03502" iyz="0.0" izz="0.00667"/>
    </inertial>
  </link>
  <!-- Configuration of the part called 'Joint 3'. -->
  <joint name="joint_3" type="revolute">
    <parent link="link_2"/>
    <child link="link_3"/>
    <origin rpy="0.0 0.0 0.0" xyz="-0.24365 0.0 0.0"/>
    <axis xyz="0 0 1"/>
    <limit effort="28.0" lower="-3.14159" upper="3.14159" velocity="3.14"/>
  </joint>
  <link name="link_3">
    <visual>
      <geometry>
        <mesh filename="/Mesh/Visual/Joint_3.stl"/>
      </geometry>
      <material name="Custom_Color">
        <color rgba="0.90 0.90 0.90 1.0"/>
      </material>
    </visual>
    <collision>
      <geometry>
        <mesh filename="/Mesh/Collision/Joint_3.stl"/>
      </geometry>
    </collision>
    <inertial>
      <mass value="1.26"/>
      <origin rpy="0.0 0.0 0.0" xyz="-0.10402 -0.00001 0.02942"/>
      <inertia ixx="0.00900" ixy="0.0" ixz="0.0" iyy="0.00940" iyz="0.0" izz="0.00158"/>
    </inertial>
  </link>
  <!-- Configuration of the part called 'Joint 4'. -->
  <joint name="joint_4" type="revolute">
    <parent link="link_3"/>
    <child link="link_4"/>
    <origin rpy="0.0 0.0 0.0" xyz="-0.21325 0.0 0.11235"/>
    <axis xyz="0 0 1"/>
    <limit effort="28.0" lower="-3.14159" upper="3.14159" velocity="3.14"/>
  </joint>
  <link name="link_4">
    <visual>
      <geometry>
        <mesh filename="/Mesh/Visual/Joint_4.stl"/>
      </geometry>
      <material name="Custom_Color">
        <color rgba="0.90 0.90 0.90 1.0"/>
      </material>
    </visual>
    <collision>
      <geometry>
        <mesh filename="/Mesh/Collision/Joint_4.stl"/>
      </geometry>
    </collision>
    <inertial>
      <mass value="1.26"/>
      <origin rpy="0.0 0.0 0.0" xyz="-0.10402 -0.00001 0.02942"/>
      <inertia ixx="0.00082" ixy="0.0" ixz="0.0" iyy="0.00067" iyz="0.0" izz="0.00094"/>
    </inertial>
  </link>
  <!-- Configuration of the part called 'Joint 5'. -->
  <joint name="joint_5" type="revolute">
    <parent link="link_4"/>
    <child link="link_5"/>
    <origin rpy="1.57080 0.0 0.0" xyz="0.0 -0.08535 0.0"/>
    <axis xyz="0 0 1"/>
    <limit effort="28.0" lower="-3.14159" upper="3.14159" velocity="3.14"/>
  </joint>
  <link name="link_5">
    <visual>
      <geometry>
        <mesh filename="/Mesh/Visual/Joint_5.stl"/>
      </geometry>
      <material name="Custom_Color">
        <color rgba="0.90 0.90 0.90 1.0"/>
      </material>
    </visual>
    <collision>
      <geometry>
        <mesh filename="/Mesh/Collision/Joint_5.stl"/>
      </geometry>
    </collision>
    <inertial>
      <mass value="1.26"/>
      <origin rpy="0.0 0.0 0.0" xyz="-0.10402 -0.00001 0.02942"/>
      <inertia ixx="0.00080" ixy="0.0" ixz="0.0" iyy="0.00067" iyz="0.0" izz="0.00092"/>
    </inertial>
  </link>
  <!-- Configuration of the part called 'Joint 6'. -->
  <joint name="joint_6" type="revolute">
    <parent link="link_5"/>
    <child link="link_6"/>
    <origin rpy="-1.57080 0.0 0.0" xyz="0.0 0.08190 0.0"/>
    <axis xyz="0 0 1"/>
    <limit effort="28.0" lower="-3.14159" upper="3.14159" velocity="3.14"/>
  </joint>
  <link name="link_6">
    <visual>
      <geometry>
        <mesh filename="/Mesh/Visual/Joint_6.stl"/>
      </geometry>
      <material name="Custom_Color">
        <color rgba="0.90 0.90 0.90 1.0"/>
      </material>
    </visual>
    <collision>
      <geometry>
        <mesh filename="/Mesh/Collision/Joint_6.stl"/>
      </geometry>
    </collision>
    <inertial>
      <mass value="1.26"/>
      <origin rpy="0.0 0.0 0.0" xyz="-0.10402 -0.00001 0.02942"/>
      <inertia ixx="0.00026" ixy="0.0" ixz="0.0" iyy="0.00016" iyz="0.0" izz="0.00019"/>
    </inertial>
  </link>
  <!-- Configuration of the part called 'End-Effector (EE)'. -->
  <joint name="tool0" type="fixed">
    <origin rpy="0.0 0.0 0.0" xyz="0.0 0.0 0.0"/>
    <parent link="link_3"/>
    <child link="tool0_link"/>
  </joint>
  <link name="tool0_link"/>
</robot>
